> 原文地址：https://www.fuzzingbook.org/html/ExpectError.html

# Error Handling

通常，代码中的错误会导致程序停止执行；无限循环则会导致程序无休止地运行。本文提供两个类解决这一问题：

## Prerequisites

以下内容需要你了解一些Python中的高级概念：

- classes ： 类，面向对象编程中的概念
- with statement： with语句
- tracing ：跟踪Python语句的执行
- measuring time ：时间测量
- exceptions：：错误

## Catching Errors(捕捉错误)

`ExpectError`类允许表达出某些代码会产生异常，用法如下：

```python
from ExpectError import ExpectError

with ExpectError():
    function_that_is_supposed_to_fail()
```

如果出现了错误，将会打印出标准错误，反之，代码继续执行

> `ExpectError`的典型用法:
>
> - 用`with`语句包装预期会出错的代码块。如果代码块中产生了异常,则不会报告错误,执行流程继续。
> - 如果没有产生异常,则会在 with 块结束时抛出 AssertionError 报告错误。
>
> 也就是说,`ExpectError`的作用是验证代码是否按预期产生了异常。

```python
import traceback
import sys
from types import FrameType, TracebackType

class ExpectError:
    def __init__(self, exc_type: [type] = None,
                 print_traceback: bool = True, mute: bool = False):
        self.print_traceback = print_traceback
        self.mute = mute
        self.expected_exc_type = exc_type

    def __enter__(self):
        return self

    def __exit__(self, exc_type: type,
                 exc_value: BaseException, tb: TracebackType) :
        if exc_type is None:
            return

        if (self.expected_exc_type is not None
            and exc_type != self.expected_exc_type):
            raise

        if self.print_traceback:
            lines = ''.join(
                traceback.format_exception(
                    exc_type,
                    exc_value,
                    tb)).strip()
        else:
            lines = traceback.format_exception_only(
                exc_type, exc_value)[-1].strip()

        if not self.mute:
            print(lines, "(expected)", file=sys.stderr)
        return True

def fail_test():
    x=1/0

if __name__ == "__main__":
    with ExpectError():
    fail_test()
```

上面的`ExpectError`类实现了一个context manager,允许在with块中执行可能会产生异常的代码,并且可以灵活地处理这些异常。

> context manager ：https://zhuanlan.zhihu.com/p/28049211

1. `__init__`：构造函数，用于初始化对象的属性。它接受三个参数：

- `exc_type`：指定一个异常类型，如果发生这个异常，那么异常将被视为已预期的异常。None则是接受所有异常
- `print_traceback`：一个布尔值，控制是否打印完整的异常回溯信息（traceback）
- `mute`（可选参数）：一个布尔值，控制是否将异常信息屏蔽，即不打印异常信息。

2.`__enter__(self):`：上下文管理器的进入方法。不接受其他参数，只需返回 `self`，表示进入上下文管理器。

3.`__exit__`：上下文管理器的退出方法，当退出上下文管理器时会自动调用它，接受3个参数

- `exc_type`：异常类型
- `exc_value`：表示发生的异常的实例
- `tb`：表示异常的回溯信息

首先检查 `exc_type` 是否为 `None`，如果为 `None`，则表示没有发生异常，直接返回，不进行任何处理。如果 `exc_type` 不为 `None`，则继续检查 `self.expected_exc_type` 是否不为 `None` 且与 `exc_type` 不相等，如果它们不相等，就会重新引发异常。

如果需要打印完整的异常回溯信息（`self.print_traceback` 为 `True`），则将回溯信息格式化为字符串并存储在 `lines` 变量中。

最后，如果 `self.mute` 为 `False`，则打印 `lines` 中的异常信息，表示异常已被捕获（如果 `self.mute` 为 `True`，则不会打印异常信息）。

上面我们用with语句来执行了一个有明显错误的方法，报错如下：

![image](https://github.com/kksaert/fuzzbook/assets/83335903/e3f6d16a-68b5-4b59-812c-d1b41096eaba)


我们直接执行，报错如下：

![image](https://github.com/kksaert/fuzzbook/assets/83335903/df5d738b-b0c1-4dce-87c9-8e8fb7322c43)


唯一的区别在于使用`with ExpectError():`的报错是我们预先知道的

---

```c
with ExpectError(print_traceback=False):
    fail_test()
```

不打印回溯信息：

![image](https://github.com/kksaert/fuzzbook/assets/83335903/386d8eef-a186-4534-afcc-83819aace871)


---

还可以特别指定错误类型，如果有其他的错误，就会通知我们

```c
with ExpectError(ZeroDivisionError):
    fail_test()
```

![image](https://github.com/kksaert/fuzzbook/assets/83335903/844079b8-5466-435f-aecd-ec01936959d7)


```c
with ExpectError():
    with ExpectError(ZeroDivisionError):
        some_nonexisting_function()
```

![Uploading image.png…]()




## Catching Timeouts

`ExpectTimeout(seconds)`类允许表达某段代码可能运行很长时间或无限时间，在经过seconds秒后会中断执行，用法如下：

```c
from ExpectError import ExpectTimeout

with ExpectTimeout(2) as t:
    function_that_is_supposed_to_hang()
```

`ExpectTimeout`类设定一个2秒的超时期限，用来运行`function_that_is_supposed_to_hang()`函数。如果在这2秒内出现异常，该异常会被打印到标准错误输出，但程序的执行会继续进行。

如果在"with"块内有需要取消超时的情况，可以使用"t.cancel()"来取消超时限制。

这个实现使用了"sys.settrace()"来实现超时控制，因为这似乎是实现超时的最通用方法。然而，需要注意的是，这种实现并不是非常高效，并且它只在单独的Python代码行上起作用，不能中断长时间运行的系统函数。也就是说，它只能控制Python代码的执行，不能控制底层系统函数的执行。

```python
import sys
import time
import traceback
from types import TracebackType
from typing import Union, Optional
from Timeout import Timeout


class ExpectTimeout(Timeout):

    def __init__(self, timeout: Union[int, float],
                 print_traceback: bool = True, mute: bool = False):
        super().__init__(timeout)
        self.print_traceback = print_traceback
        self.mute = mute

    def __exit__(self, exc_type: type,
                 exc_value: BaseException, tb: TracebackType) -> Optional[bool]:
        super().__exit__(exc_type, exc_value, tb)

        if exc_type is None:
            return

        if self.print_traceback:
            lines = ''.join(
                traceback.format_exception(
                    exc_type,
                    exc_value,
                    tb)).strip()
        else:
            lines = traceback.format_exception_only(
                exc_type, exc_value)[-1].strip()

        if not self.mute:
            print(lines, "(expected)", file=sys.stderr)

        return True  

def long_running_test() -> None:
    print("Start")
    for i in range(10):
        time.sleep(1)
        print(i, "seconds have passed")
    print("End")

if __name__ == "__main__":
    with ExpectTimeout(5, print_traceback=False):
        long_running_test()
```

> 注意`from Timeout import Timeout`是别的章节的，所以上面的代码不能直接使用，和上面的错误处理代码类似，这里不实际操作

代码给了一个5秒的超时，且不打印错误回溯信息，运行结果如下

```c
Start
0 seconds have passed
1 seconds have passed
2 seconds have passed
3 seconds have passed
TimeoutError (expected)
```

设置多层超时，报错如下：

```c
with ExpectTimeout(5, print_traceback=False):
    with ExpectTimeout(3, print_traceback=False):
        long_running_test()
    long_running_test()
```

```c
Start
0 seconds have passed
1 seconds have passed
TimeoutError (expected)
Start
0 seconds have passed
1 seconds have passed
2 seconds have passed
3 seconds have passed
TimeoutError (expected)
```

